
# üìÑ Ejemplo pr√°ctico completo: An√°lisis de textos con manejo de errores

Veamos ahora un ejemplo integral para aplicar todo lo anterior. Supongamos que queremos hacer un peque√±o analizador de textos: nuestro programa va a leer varios archivos de texto y contar cu√°ntas palabras tiene cada uno, y al final dar un total de palabras procesadas. Este escenario nos permitir√° ver manejo de excepciones con archivos (por si alg√∫n archivo no existe) y la decisi√≥n de reportar o no ciertos errores al usuario.

Imaginemos que tenemos una lista de nombres de archivos de texto (podr√≠an ser archivos de libros obtenidos de Project Gutenberg u otra fuente). Algunos archivos pueden existir y otros no, para simular distintos casos. Queremos que el programa procese todos los archivos que pueda y no se detenga si uno falla. Aqu√≠ est√° una posible implementaci√≥n:

```python
archivos = ["texto1.txt", "texto2.txt", "novela.txt", "inexistente.txt"]
total_palabras = 0
for archivo in archivos:
    try:
        with open(archivo, "r", encoding="utf-8") as f:
            contenido = f.read()
    except FileNotFoundError:
        print(f"Advertencia: el archivo {archivo} no se encontr√≥. Se omitir√°.")
        continue
    except Exception as e:
        print(f"No se pudo procesar {archivo} por un error inesperado:", e)
        continue
    # Si llegamos aqu√≠, la lectura fue exitosa
    palabras = contenido.split()
    print(f"{archivo}: {len(palabras)} palabras")
    total_palabras += len(palabras)
print("Total de palabras procesadas:", total_palabras)
```

**Explicaci√≥n del c√≥digo:**

- Definimos una lista `archivos` con cuatro nombres. Supongamos que "inexistente.txt" no existe en el directorio, para ver qu√© pasa.
- Recorremos cada nombre en la lista. Para cada archivo, intentamos abrirlo en modo lectura ("r") con codificaci√≥n UTF-8 (para soportar acentos, etc.), utilizando un bloque `with`. Usamos `with open(..., "r") as f` porque es una forma recomendada que autom√°ticamente cerrar√° el archivo al terminar de usarlo.
- Si el archivo no existe, `open` lanza `FileNotFoundError` y saltamos al bloque `except FileNotFoundError`. All√≠ imprimimos una advertencia amigable al usuario, indicando que ese archivo se omitir√°. Luego `continue` hace que pasemos al siguiente archivo de la lista sin ejecutar lo que queda del bucle para el archivo actual.
- Tambi√©n incluimos un `except Exception as e` gen√©rico. Esto capturar√° cualquier otra excepci√≥n que pueda ocurrir durante la lectura (por ejemplo, si no tuvi√©ramos permiso de leer el archivo, Python lanzar√≠a `PermissionError`, que caer√≠a aqu√≠). En tal caso, informamos que no se pudo procesar ese archivo por un error inesperado, mostramos el mensaje `e` para detalles t√©cnicos, y continuamos con el siguiente archivo.
- Si el `with open` tiene √©xito (no hubo excepci√≥n), pasamos a la siguiente parte del bucle: contamos las palabras del contenido. Utilizamos `str.split()` sin argumentos para separar por espacios en blanco (espacios, saltos de l√≠nea, tabs) y obtenemos una lista de palabras, luego `len` para contar cu√°ntas hay.
- Imprimimos el resultado parcial: cu√°ntas palabras ten√≠a el archivo procesado.
- Acumulamos el conteo en `total_palabras`.
- Despu√©s del bucle, imprimimos el total de palabras contadas entre todos los archivos procesados exitosamente.

**Salida esperada:**

```
texto1.txt: 1200 palabras
texto2.txt: 950 palabras
novela.txt: 53400 palabras
Advertencia: el archivo inexistente.txt no se encontr√≥. Se omitir√°.
Total de palabras procesadas: 55550
```

Observa que:
- Proces√≥ los tres primeros archivos y mostr√≥ sus conteos.
- Al llegar a `inexistente.txt`, lanz√≥ la advertencia pero no se detuvo el programa; simplemente no sum√≥ nada de ese archivo.
- Al final dio el total solo de los archivos que s√≠ pudo leer.
- Gracias al manejo de excepciones, ning√∫n error detuvo el programa por completo. Sin `try/except`, el programa habr√≠a crasheado en el intento de abrir `inexistente.txt` y nunca habr√≠a mostrado los resultados de los otros archivos.

¬øDebemos reportar todos los errores al usuario? Depende del caso de uso:
- Si el usuario sab√≠a qu√© archivos deb√≠an procesarse (por ejemplo, porque √©l mismo nos dio la lista), seguramente espera o agradece saber que 'inexistente.txt' no se pudo analizar y por qu√©. As√≠ puede corregir el nombre o a√±adir el archivo que falta.
- Pero si la lista de archivos es interna del programa y el usuario solo espera un resultado global, tal vez podr√≠amos optar por no mostrar un mensaje por cada archivo faltante y simplemente al final indicar "Algunos archivos no pudieron ser le√≠dos" o incluso no mencionar nada si no es crucial. Esto para no abrumar con detalles innecesarios.

En nuestro ejemplo imprimimos un mensaje de advertencia con cada archivo omitido, lo cual est√° bien para transparencia en muchos casos. Lo importante es tomar una decisi√≥n consciente sobre la comunicaci√≥n de errores: brindar informaci√≥n √∫til, pero no saturar al usuario con mensajes que no le sirven. Siempre que se omite un error (errores silenciosos), hazlo porque no afecta al prop√≥sito principal desde la perspectiva del usuario. Si afecta, entonces debe saberse.



# üèã Ejercicios de pr√°ctica (con enunciado y soluci√≥n explicada)

A continuaci√≥n te proponemos una serie de ejercicios para practicar el manejo de excepciones en Python. Cada ejercicio incluye un enunciado (el problema a resolver), una posible estructura o pista para ayudarte a encaminar la soluci√≥n, y finalmente una soluci√≥n propuesta con explicaci√≥n. ¬°No dudes en intentar resolverlos por tu cuenta primero antes de ver la soluci√≥n! üí™

## Ejercicio 1: Divisi√≥n segura

**Enunciado:**

Escribe un programa que solicite al usuario dos n√∫meros (un numerador y un denominador) y muestre el resultado de la divisi√≥n del numerador por el denominador. Si el usuario ingresa un valor que no es num√©rico, el programa debe detectar el error y avisar con un mensaje sin terminar abruptamente. Si el denominador es cero, el programa no debe intentar dividir (ya que causar√≠a un error); en su lugar, debe imprimir un mensaje indicando que la divisi√≥n por cero no es posible.

**Pista (Estructura sugerida):**

Necesitar√°s usar `input()` para obtener los valores, convertirlos a tipo num√©rico (por ejemplo `int` o `float`), y usar un bloque `try/except` para englobar la operaci√≥n de divisi√≥n. Debes manejar al menos dos tipos de excepci√≥n: una para el caso en que la conversi√≥n de entrada a n√∫mero falle (`ValueError`) y otra para la divisi√≥n por cero (`ZeroDivisionError`). El flujo podr√≠a ser:

- Pedir numerador y denominador al usuario.
- Intentar convertirlos a n√∫mero y dividir.
- Si ocurre un `ValueError` en la conversi√≥n, notificar al usuario que la entrada no era v√°lida.
- Si ocurre `ZeroDivisionError` en la divisi√≥n, notificar sobre divisi√≥n por cero.
- Si todo sale bien, mostrar el resultado.

**Soluci√≥n propuesta:**

```python
try:
    num = float(input("Numerador: "))
    den = float(input("Denominador: "))
    resultado = num / den
except ValueError:
    print("‚ùå Debes ingresar un n√∫mero v√°lido.")
except ZeroDivisionError:
    print("‚ùå Error: No se puede dividir entre cero.")
else:
    print(f"‚úÖ Resultado: {resultado}")
```

**Explicaci√≥n:**

En este c√≥digo, englobamos toda la secuencia de leer entradas, convertir a float y dividir dentro de un `try`. Esto porque tanto la conversi√≥n a float como la divisi√≥n pueden producir excepciones. Manejos implementados:

- Si el usuario ingresa algo que no puede convertirse a n√∫mero (ej: "abc" o "5,3" con coma en vez de punto decimal), la conversi√≥n a float lanza `ValueError`. Capturamos ese error y mostramos un mensaje indic√°ndolo. De este modo, el programa no se cierra abruptamente con un traceback feo, sino que informa elegantemente del problema.
- Si la conversi√≥n va bien pero luego el denominador resulta ser 0, la operaci√≥n numerador / denominador lanza `ZeroDivisionError`. Nuestro segundo bloque except captura ese caso y avisa del error espec√≠fico de divisi√≥n por cero.
- Usamos un bloque `else` despu√©s de los except: esto se ejecutar√° solo si no hubo ninguna excepci√≥n. En ese caso, significa que la divisi√≥n se realiz√≥ con √©xito, as√≠ que mostramos el resultado normalmente.
- Los iconos (‚ùå y ‚úÖ) en los mensajes son opcionales, solo para hacer m√°s claro visiblemente qu√© es error y qu√© es √©xito.
- Si quisi√©ramos, podr√≠amos pedir los n√∫meros en un loop hasta que ingrese datos correctos; pero aqu√≠, con un solo intento, ilustramos el manejo b√°sico de errores. Siempre podr√≠as envolver esto en un `while True` para repetir la pregunta en caso de error, saliendo del loop (`break`) solo cuando logre obtener un resultado (usando el bloque `else` como indicador de √©xito).

---

## Ejercicio 2: Lectura de archivo con reintento

**Enunciado:**

Crea un programa que le pida al usuario el nombre de un archivo de texto a abrir. Intenta abrir el archivo y leer su contenido. Si el archivo no existe (`FileNotFoundError`), el programa debe informar al usuario y darle otra oportunidad de ingresar un nombre de archivo, en lugar de terminar con error. Si el archivo se abre correctamente, muestra en pantalla la primera l√≠nea del archivo (o todo su contenido, como prefieras) y termina.

**Pista (Estructura sugerida):**

Aqu√≠ es √∫til usar un bucle para seguir preguntando mientras falle. Por ejemplo:

- Mientras True (bucle infinito):
    - Pedir al usuario el nombre de archivo.
    - Intentar abrir el archivo dentro de un try.
    - Si se abre con √©xito, quiz√°s usar un break para salir del bucle.
    - Si lanza `FileNotFoundError`, informar y el loop contin√∫a, solicitando de nuevo.
- Despu√©s del loop, si salimos porque logramos abrir (habr√°s hecho un break), entonces procede a leer del archivo y mostrar lo requerido.

**Soluci√≥n propuesta:**

```python
while True:
    nombre = input("Ingrese el nombre del archivo: ")
    try:
        with open(nombre, "r") as archivo:
            lineas = archivo.readlines()
        break
    except FileNotFoundError:
        print("Archivo no encontrado, intenta nuevamente.")
    except Exception as e:
        print("Error al abrir el archivo:", e)
        print("Intenta nuevamente.")

# Si llegamos aqu√≠, significa que `lineas` tiene el contenido le√≠do con √©xito
if lineas:
    print("Primera l√≠nea:", lineas[0].strip())
else:
    print("El archivo est√° vac√≠o.")
```

**Explicaci√≥n:**

- Usamos un bucle `while True` para permitir m√∫ltiples intentos de ingreso.
- Dentro del `try`, usamos `with open(..., "r") as archivo:` para intentar abrir el nombre dado en modo lectura. Si el archivo no existe, saltaremos al `except FileNotFoundError` antes de llegar a leer.
- Si `open` falla por archivo no encontrado, informamos al usuario y usamos `continue` para volver a la cabecera del `while` y pedir otro nombre. Esto seguir√° hasta que el `open` funcione.
- Tambi√©n agregamos un `except Exception as e` general, por si ocurre alg√∫n otro error al intentar abrir (por ejemplo, un problema de permisos, `PermissionError`, o un error de decodificaci√≥n de caracteres). En tal caso, tambi√©n informamos y permitimos reintentar. (Dependiendo del caso, se podr√≠a manejar distintos tipos de error por separado, pero para mantenerlo simple cualquier otro error inesperado tambi√©n provoca un nuevo intento).
- Si el archivo se abre correctamente, el c√≥digo dentro del `with` se ejecuta: leemos todas las l√≠neas con `archivo.readlines()`. Luego salimos del bloque `with` (lo que cierra el archivo autom√°ticamente) y procedemos al `break` fuera de los except, que rompe el bucle porque ya tuvimos √©xito.
- Despu√©s del bucle, estamos seguros de que `lineas` tiene las l√≠neas del archivo (porque la √∫nica forma de salir del loop es habiendo ejecutado `break` tras una lectura exitosa). Entonces revisamos: si `lineas` no est√° vac√≠o, imprimimos la primera l√≠nea (quitando el salto de l√≠nea final con `.strip()` para est√©tica). Si `lineas` est√° vac√≠o, significa que el archivo exist√≠a pero estaba vac√≠o, as√≠ que informamos eso.

Este programa le permite al usuario intentar varios nombres hasta dar con uno v√°lido. Si hubi√©ramos no usado el loop y dejado que el programa termine en caso de error, ser√≠a menos interactivo. Aqu√≠ aplicamos control de flujo usando excepciones para mejorar la experiencia de uso.

---

## Ejercicio 3: Excepci√≥n personalizada (contrase√±a segura)

**Enunciado:**

Imagina que est√°s creando un sistema de registro de usuarios y necesitas verificar la fortaleza de una contrase√±a. Escribe una funci√≥n `verificar_contrase√±a(password)` que verifique si la contrase√±a cumple ciertos criterios, por ejemplo uno b√°sico: al menos 8 caracteres. Si la contrase√±a es muy corta, la funci√≥n deber√≠a lanzar una excepci√≥n personalizada llamada `Contrase√±aCortaError`. Si la contrase√±a cumple con el criterio, la funci√≥n puede devolver `True` (o simplemente no lanzar nada). Luego, escribe c√≥digo que use dicha funci√≥n dentro de un bloque `try/except` para probarla: pide al usuario una contrase√±a, la validas con `verificar_contrase√±a` y capturas la excepci√≥n `Contrase√±aCortaError` para notificar al usuario en caso de que falle la validaci√≥n. Si no hay excepci√≥n, felicita al usuario por una contrase√±a v√°lida.

**Pista:**

Para crear la excepci√≥n personalizada, define una clase heredando de `Exception` con el nombre `Contrase√±aCortaError`. Dentro de la funci√≥n, puedes verificar la longitud con `len(password)`. Para lanzar la excepci√≥n usa `raise Contrase√±aCortaError("tu mensaje")`. En el uso, rodea la llamada en `try`, y en `except` especifica `Contrase√±aCortaError as e` para capturarla. Puedes tambi√©n agregar m√°s criterios (may√∫sculas, n√∫meros, etc.) si lo deseas, pero para el ejercicio nos centramos en la longitud.

**Soluci√≥n propuesta:**

```python
# Definir la excepci√≥n personalizada
class Contrase√±aCortaError(Exception):
    """Excepci√≥n lanzada cuando la contrase√±a es demasiado corta."""
    pass

# Funci√≥n de verificaci√≥n
def verificar_contrase√±a(password):
    if len(password) < 8:
        raise Contrase√±aCortaError(f"tu contrase√±a solo tiene {len(password)} caracteres, requieren al menos 8 caracteres.")
    return True

# Programa principal
try:
    pwd = input("Introduce una contrase√±a: ")
    verificar_contrase√±a(pwd)
except Contrase√±aCortaError as e:
    print("Contrase√±a no v√°lida:", e)
else:
    print("Contrase√±a v√°lida. ¬°Registro exitoso!")
```

**Explicaci√≥n:**

- Primero definimos la clase `Contrase√±aCortaError` heredando de `Exception`. No tiene m√°s contenido que un docstring explicativo, pero podr√≠amos extenderla si quisi√©ramos (por ejemplo, almacenar la longitud requerida como atributo).
- La funci√≥n `verificar_contrase√±a` chequea la longitud de la cadena `password`. Si es menor que 8, usamos `raise` para lanzar una nueva instancia de `Contrase√±aCortaError` con un mensaje. Ese mensaje incluye la longitud actual para informaci√≥n.
- Si la contrase√±a tiene 8 o m√°s caracteres, la funci√≥n retorna `True` (en realidad podr√≠amos no retornar nada espec√≠fico y simplemente salir sin excepci√≥n, que equivale a √©xito; aqu√≠ retornamos `True` expl√≠citamente por claridad).
- En el programa principal, pedimos al usuario una contrase√±a. Luego llamamos a `verificar_contrase√±a(pwd)` dentro de un `try`.
- Si la contrase√±a es suficientemente larga, la funci√≥n devuelve `True` y no lanza excepci√≥n. Pasamos entonces el bloque `try` exitosamente y mostramos "Contrase√±a v√°lida".
- Si la contrase√±a es corta, la funci√≥n lanza `Contrase√±aCortaError`. Inmediatamente se interrumpe el flujo normal y saltamos al `except Contrase√±aCortaError as e`. All√≠, capturamos la excepci√≥n en la variable `e` y mostramos un mensaje de error al usuario, incluyendo el mensaje original de la excepci√≥n (que hab√≠amos definido al hacer `raise`, indicando cu√°n corta era).
- Observa que estamos capturando espec√≠ficamente `Contrase√±aCortaError`. Si ocurriera alguna otra excepci√≥n no prevista (por ejemplo, un `TypeError` porque pasamos un objeto no `str` a `len`, caso poco probable aqu√≠), no la capturamos, lo cual est√° bien porque no la anticipamos; se propagar√° fuera del `try` (en un programa real podr√≠amos a√±adir un `except Exception` general para no romper, pero en este contexto de prueba nos enfocamos en nuestra excepci√≥n).
- El uso de excepciones personalizadas hace el c√≥digo m√°s claro: lanzamos `Contrase√±aCortaError` cuando esa condici√≥n espec√≠fica falla, en lugar de reutilizar, digamos, un `ValueError` gen√©rico. As√≠, en el bloque que llama a la funci√≥n, queda muy expl√≠cito qu√© estamos intentando capturar.